<robot name="bravo5">
    <link name="base_link"/>
    <material name="bravo_black">
    <color rgba="0.3 0.3 0.3 1"/>
    </material>
    <joint name="bravo_joint" type="fixed">
        <origin rpy="0 0 0" xyz="0 0 0"/>
        <parent link="base_link"/>
        <child link="bravo_base_link"/>
    </joint>
    <link name="bravo_base_link"/>


    <link name="bravo_rs2_266_link">
        <visual>
            <geometry>
                <mesh filename="package://bravo_description/meshes/RS2-266.stl"/>
            </geometry>
            <material name="bravo_black"/>
        </visual>
    </link>

    <joint name="bravo_rs2_266_joint" type="fixed">
        <parent link="bravo_base_link"/>
        <child link="bravo_rs2_266_link"/>
        <origin rpy="0 0 0"/>
    </joint>

    <link name="bravo_rs2_217_link">
        <visual>
            <geometry>
                <mesh filename="package://bravo_description/meshes/RS2-217.stl"/>
            </geometry>
            <material name="bravo_black"/>
        </visual>
    </link>

    <joint name="bravo_axis_e" type="revolute">
        <parent link="bravo_rs2_266_link"/>
        <child link="bravo_rs2_217_link"/>
        <origin rpy="0 0 0" xyz="0.0665 0 0.078"/>
        <axis xyz="0 0 -1"/>
        <limit effort="9.0" lower="0.0" upper="6.3" velocity="0.5"/>
    </joint>

    <link name="bravo_rs2_250_212_214_link">
        <visual>
            <geometry>
                <mesh filename="package://bravo_description/meshes/RS2-250-212-214.stl"/>
            </geometry>
            <material name="bravo_black"/>
        </visual>
    </link>

    <joint name="bravo_axis_d" type="revolute">
        <parent link="bravo_rs2_217_link"/>
        <child link="bravo_rs2_250_212_214_link"/>
        <origin rpy="0 0 0" xyz="-0.046 0 0.0674"/>
        <axis xyz="0 1 0"/>
        <limit effort="9.0" lower="0.0" upper="3.5" velocity="0.5"/>
    </joint>

    <link name="bravo_rs2_268_link">
        <visual>
            <geometry>
                <mesh filename="package://bravo_description/meshes/RS2-268.stl"/>
            </geometry>
            <material name="bravo_black"/>
        </visual>
    </link>

    <joint name="bravo_axis_c" type="revolute">
        <parent link="bravo_rs2_250_212_214_link"/>
        <child link="bravo_rs2_268_link"/>
        <origin rpy="0 0 0" xyz="-0.0052 0 -0.29355"/>
        <axis xyz="0 1 0"/>
        <limit effort="9.0" lower="0.0" upper="3.5" velocity="0.5"/>
    </joint>

    <link name="bravo_rs2_180_link">
        <visual>
            <geometry>
                <mesh filename="package://bravo_description/meshes/RS2-180.stl"/>
            </geometry>
            <material name="bravo_black"/>
        </visual>
    </link>


    <joint name="bravo_axis_b" type="revolute">
        <parent link="bravo_rs2_268_link"/>
        <child link="bravo_rs2_180_link"/>
        <origin rpy="0 0 0" xyz="0.0408 0 0.09645"/>
        <axis xyz="0 0 -1"/>
        <limit effort="9.0" lower="0.0" upper="6.3" velocity="0.5"/>
    </joint>

    <joint name="bravo_jaws_joint" type="fixed">
    <origin rpy="0 0 0" xyz=" 0 0 0.124"/>
    <parent link="bravo_rs2_180_link"/>
    <child link="bravo_jaws_base_link"/>
  </joint>

    <material name="bravo_jaws_black">
    <color rgba="0.3 0.3 0.3 1"/>
  </material>
    <link name="bravo_jaws_base_link">
        <visual>
            <geometry>
                <mesh filename="package://bravo_description/meshes/end_effectors/RS2-257.stl"/>
            </geometry>
            <material name="bravo_jaws_black"/>
            </visual>
    </link>
    <link name="bravo_push_rod"/>
    <joint name="bravo_axis_a" type="prismatic">
        <origin rpy="0 0 0" xyz="0 0 0.009"/>
        <parent link="bravo_jaws_base_link"/>
        <child link="bravo_push_rod"/>
        <axis xyz="0 0 1"/>
        <limit effort="10" lower="0" upper="0.035" velocity="10"/>
    </joint>
    <link name="bravo_rs2_255_link">
        <visual>
            <geometry>
                <mesh filename="package://bravo_description/meshes/end_effectors/RS2-255.stl"/>
            </geometry>
        <material name="bravo_jaws_black"/>
        <origin rpy="0 0 0" xyz="0 0 0"/>
        </visual>
    </link>
    <joint name="bravo_rs2_255_joint" type="revolute">
        <origin rpy="0 0 0" xyz="0 0.033 0.0097"/>
        <parent link="bravo_jaws_base_link"/>
        <child link="bravo_rs2_255_link"/>
        <axis xyz="-1 0 0"/>
        <limit effort="10" lower="0" upper="0.5" velocity="10"/>
        <mimic joint="bravo_axis_a" multiplier="15" offset="0"/>
    </joint>
    <link name="bravo_rs2_255_jaw_inside_link">
        <visual>
            <geometry>
                <mesh filename="package://bravo_description/meshes/end_effectors/RS2-255-Jaw-Inside.stl"/>
            </geometry>
            <material name="bravo_jaws_black"/>
            <origin rpy="0 0 0" xyz="0 0 0"/>
        </visual>
    </link>
    <joint name="bravo_rs2_255_jaw_inside_joint" type="revolute">
        <origin rpy="0 0 0" xyz="0 -0.033 0.0097"/>
        <parent link="bravo_jaws_base_link"/>
        <child link="bravo_rs2_255_jaw_inside_link"/>
        <axis xyz="1 0 0"/>
        <limit effort="10" lower="0" upper="0.5" velocity="10"/>
        <mimic joint="bravo_axis_a" multiplier="15" offset="0"/>
    </joint>
</robot>